<?xml version="1.0"?>
<!-- Basic WAM-V with gazebo plugins for dynamics -->
<robot xmlns:xacro="http://ros.org/wiki/xacro"
       name="lpv-4">
  <xacro:arg name="locked" default="false" />
  <xacro:arg name="thruster_config" default="H" />
  <xacro:arg name="camera_enabled" default="false" />
  <xacro:arg name="gps_enabled" default="false" />
  <xacro:arg name="imu_enabled" default="false" />
  <xacro:arg name="lidar_enabled" default="false" />
  <xacro:arg name="ground_truth_enabled" default="false" />
  <xacro:arg name="aimm_sensors_enabled" default="false" />
  <xacro:arg name="pinger_enabled" default="false" />
  <xacro:arg name="ball_shooter_enabled" default="false" />
  <xacro:arg name="thruster_namespace" default="thrusters/"/>
  <xacro:arg name="camera_namespace" default="cameras/"/>  
  <xacro:arg name="sensor_namespace" default="sensors/"/>
  <xacro:arg name="pinger_namespace" default="pingers/"/>
  <xacro:arg name="shooter_namespace" default="shooters/"/>
  <!-- Note: this is only used for some sensors that do not correctly use the 
  robotNamespace parameter -->
  <xacro:arg name="namespace" default="lpv"/>    
  <xacro:property name="thruster_namespace" value="$(arg thruster_namespace)" scope="global" />
  <xacro:property name="camera_namespace" value="$(arg camera_namespace)" scope="global" />
  <xacro:property name="sensor_namespace" value="$(arg sensor_namespace)" scope="global" />
  <xacro:property name="pinger_namespace" value="$(arg pinger_namespace)" scope="global" />
  <xacro:property name="shooter_namespace" value="$(arg shooter_namespace)" scope="global" />
  <xacro:property name="namespace" value="$(arg namespace)" scope="global" />      
  
  <!-- Sensor yaml file -->
  <xacro:arg name="yaml_component_generation" default="false"/>
  <xacro:arg name="component_xacro_file" default = ""/>

  <!-- Thruster yaml file -->
  <xacro:arg name="yaml_thruster_generation" default="false"/>
  <xacro:arg name="thruster_xacro_file" default = ""/>

  <!-- === The LP-V platform === -->
  <xacro:include filename="$(find lpv_gazebo)/urdf/lpv_gazebo.xacro"/>
  


  <!-- === Thrusters === -->
  <!-- Use thruster yaml file if given -->
  <xacro:if value="$(arg yaml_thruster_generation)">
    <xacro:lpv_gazebo thruster_layout="$(arg thruster_xacro_file)"/>
  </xacro:if>
  
  <!-- Otherwise, add thrusters based on thruster_config variable -->
  <xacro:unless value="$(arg yaml_thruster_generation)">
    <xacro:property name="thruster_conf" value="$(arg thruster_config)"/>

    <!-- Default WAM-V with two aft thrusters -->
    <xacro:if value="${thruster_conf == 'H'}">
       <xacro:lpv_gazebo thruster_layout="$(find lpv_gazebo)/urdf/thruster_layouts/lpv_aft_thrusters.xacro"/>
    </xacro:if>

    <!-- WAMV with "T" thruster configuration -->
    <xacro:if value="${thruster_conf == 'T'}">
      <xacro:lpv_gazebo thruster_layout="$(find lpv_gazebo)/urdf/thruster_layouts/lpv_t_thrusters.xacro"/>
    </xacro:if>

    <!-- WAMV with "X" thruster configuration -->
    <xacro:if value="${thruster_conf == 'X'}">
      <xacro:lpv_gazebo thruster_layout="$(find lpv_gazebo)/urdf/thruster_layouts/lpv_x_thrusters.xacro"/>
    </xacro:if>
  </xacro:unless>

  <!-- === Decide if we lock the robot to the world === -->
  <xacro:if value="$(arg locked)">
    <gazebo>
      <link name="lpv_external_link"/>
      <joint name="lpv_external_pivot_joint" type="universal">
        <parent>lpv::lpv/base_link</parent>
        <child>lpv_external_link</child>
        <axis>
          <xyz>1 0 0</xyz>
        </axis>
        <axis2>
          <xyz>0 1 0</xyz>
        </axis2>
      </joint>
      <joint name="lpv_external_riser" type="prismatic">
        <parent>world</parent>
        <child>lpv_external_link</child>
        <axis>
          <limit>
            <lower>-3</lower>
            <upper>3</upper>
          </limit>
          <xyz>0 0 1</xyz>
        </axis>
      </joint>
    </gazebo>
  </xacro:if>

  <!-- === Sensors === -->
  <!-- Use sensor yaml file if given -->
  <xacro:if value="$(arg yaml_component_generation)">
    <xacro:include filename="$(arg component_xacro_file)"/>
    <xacro:yaml_components />
  </xacro:if>
  
  <!-- Otherwise, add sensors based on enable variables -->
  <xacro:unless value="$(arg yaml_component_generation)">
    
    <!-- Add a front camera -->
    <xacro:if value="$(arg camera_enabled)">
      <xacro:lpv_camera name="front_camera" y="0.3" x="0.75" P="${radians(15)}" />
    </xacro:if>
    
    <!-- Add simulated GPS -->
    <xacro:if value="$(arg gps_enabled)">
      <xacro:lpv_gps name="gps_lpv" x="-0.85" />
    </xacro:if>
    
   
    <!-- Add P3D ground truth -->
    <xacro:if value="$(arg ground_truth_enabled)">
      <xacro:lpv_p3d name="p3d_lpv"/>
    </xacro:if>



    <!-- Add pinger -->
    <xacro:if value="$(arg pinger_enabled)">
      <xacro:lpv_pinger name="pinger" position="1.0 0 -1.0" />
    </xacro:if>

    
    <!-- ==== AIMM sensor configuration ==== -->
    <xacro:if value="$(arg aimm_sensors_enabled)">
    
   
      <!-- Add a stereo camera pair -->
      <xacro:lpv_camera name="front_left_camera" y="0.7" x="-3" z="0.9" P="${radians(0)}" Y="${radians(120)}" post_Y="${radians(120)}" visualize="true"/>
      <xacro:lpv_camera name="front_right_camera" y="-0.7" x="-3" z="0.9" P="${radians(0)}" Y="${radians(-120)}" post_Y="${radians(-120)}" visualize="true"/>

    
      <!-- Add simulated GPS + Radar -->
      <xacro:lpv_gps name="gps_lpv" x="0.3" z="0.8"/>
      <xacro:lpv_radar name="radar_lpv" x="-0.85" y="0" z="0.9" P="${radians(0)}" Y="${radians(-180)}"  />



    </xacro:if>
  </xacro:unless>

</robot>
